<?xml version="1.0" ?>
<!-- =================================================================================== -->
<!-- |    This document was autogenerated by xacro from ../../urdf/vision60.urdf.xacro | -->
<!-- |    EDITING THIS FILE BY HAND IS NOT RECOMMENDED                                 | -->
<!-- =================================================================================== -->
<!--
 * Copyright (C) Ghost Robotics - All Rights Reserved
 * Unauthorized copying of this file, via any medium is strictly prohibited
 * Proprietary and confidential
 * Written by Avik De <avik@ghostrobotics.io> and Tom Jacobs <tom.jacobs@ghostrobotics.io>
-->
<robot name="ngr" xmlns:xacro="http://www.ros.org/wiki/xacro">
  <!-- Define parameters -->
  <!-- This is the joint angle offset at the hip bumper -->
  <!-- Define materials -->
  <material name="gray">
    <color rgba="0.5 0.5 0.5 1.0"/>
  </material>
  <material name="darkgray">
    <color rgba="0.3 0.3 0.3 1.0"/>
  </material>
  <material name="blue">
    <color rgba="0 0 0.8 1"/>
  </material>
  <material name="black">
    <color rgba="0 0 0 1"/>
  </material>
  <material name="purple">
    <color rgba="0.5 0.0 0.5 1.0"/>
  </material>
  <material name="red">
    <color rgba="0.8 0.0 0.2 1.0"/>
  </material>
  <!-- Body -->
  <link name="body">
    <visual>
      <origin rpy="0 0 0" xyz="0 0 0"/>
      <geometry>
        <box size="0.83 0.25 0.19"/>
      </geometry>
      <material name="gray"/>
    </visual>
    <inertial>
      <mass value="17.9"/>
      <!-- Uniform box -->
      <!-- inertia ixx="1/12*${bodyMass}*(${bodyWidth}*${bodyWidth} + ${bodyHeight}*${bodyHeight})"  ixy="0"  ixz="0" iyy="1/12*${bodyMass}*(${bodyLength}*${bodyLength} + ${bodyHeight}*${bodyHeight})" iyz="0" izz="1/12*${bodyMass}*(${bodyLength}*${bodyLength} + ${bodyWidth}*${bodyWidth})" / -->
      <inertia ixx="0.0986" ixy="0" ixz="0" iyy="0.8105" iyz="0" izz="0.8369"/>
    </inertial>
    <!-- Just copy geometry for collision -->
    <collision>
      <geometry>
        <box size="0.05 0.25 0.19"/>
      </geometry>
    </collision>
  </link>
  <!-- Define our leg macro -->
  <!-- Our four legs (with hip bumpers. But only works well in normal upside mode)
	<xacro:red_leg suffix="0" hipJointName="0" kneeJointName="1" abductionJointName="8" front="1" left="1" hipJointLowerLimit="${-hipBumper}" hipJointUpperLimit="${-hipBumper+2*pi}"/>
 	<xacro:leg suffix="1" hipJointName="2" kneeJointName="3" abductionJointName="9" front="-1" left="1" hipJointLowerLimit="${-pi-hipBumper}" hipJointUpperLimit="${pi-hipBumper}"/>
 	<xacro:leg suffix="2" hipJointName="4" kneeJointName="5" abductionJointName="10" front="1" left="-1" hipJointLowerLimit="${-hipBumper}" hipJointUpperLimit="${-hipBumper+2*pi}"/>
 	<xacro:leg suffix="3" hipJointName="6" kneeJointName="7" abductionJointName="11" front="-1" left="-1" hipJointLowerLimit="${-pi-hipBumper}" hipJointUpperLimit="${pi-hipBumper}"/>
-->
  <!-- Our four legs -->
  <!-- Hip motor -->
  <link name="hip0">
    <visual>
      <origin rpy="1.5707963268 0 0" xyz="-0.01 -0.005 0"/>
      <geometry>
        <box size="0.15 0.09 0.15"/>
      </geometry>
      <material name="red"/>
    </visual>
    <collision>
      <origin rpy="1.5707963268 0 0" xyz="0.0 -0.005 0"/>
      <geometry>
        <box size="0.15 0.09 0.15"/>
      </geometry>
    </collision>
    <inertial>
      <mass value="1.975"/>
      <!-- inertia ixx="1/12*${podMass}*(${podWidth}*${podWidth} + ${podHeight}*${podHeight})"  ixy="0"  ixz="0" iyy="1/12*${podMass}*(${podLength}*${podLength} + ${podWidth}*${podWidth})" iyz="0" izz="1/12*${podMass}*(${podLength}*${podLength} + ${podHeight}*${podHeight})" / -->
      <inertia ixx="0.00891458" ixy="0" ixz="0" iyy="0.0100573" iyz="0" izz="0.01533698"/>
    </inertial>
  </link>
  <!-- Abduction joint. Joint names are: 8 9 10 11 -->
  <joint name="8" type="revolute">
    <parent link="body"/>
    <child link="hip0"/>
    <axis xyz="1 0 0"/>
    <origin xyz="0.34385 0.092865 0"/>
    <limit effort="375" lower="-0.43" upper="0.43" velocity="8.6"/>
    <dynamics damping="0.0" friction="0.0"/>
  </joint>
  <!-- Upper leg -->
  <link name="upper0">
    <visual>
      <origin rpy="0 0 0" xyz="-0.17 0.0 0"/>
      <geometry>
        <box size="0.34 0.055 0.075"/>
      </geometry>
      <material name="blue"/>
    </visual>
    <collision>
      <origin rpy="0 0 0" xyz="-0.17 0 0"/>
      <geometry>
        <box size="0.34 0.055 0.075"/>
      </geometry>
    </collision>
    <inertial>
      <mass value="2.525"/>
      <!-- inertia ixx="1/12*${upperLegMass}*(${upperLegWidth}*${upperLegWidth} + ${upperLegHeight}*${upperLegHeight})"  ixy="0" ixz="0" iyy="1/12*${upperLegMass}*(${upperLegLength}*${upperLegLength} + ${upperLegHeight}*${upperLegHeight})" iyz="0" izz="1/12*${upperLegMass}*(${upperLegWidth}*${upperLegWidth} + ${upperLegLength}*${upperLegLength})" / -->
      <inertia ixx="0.0003125" ixy="0" ixz="0" iyy="0.0040625" iyz="0" izz="0.0040625"/>
    </inertial>
  </link>
  <!-- Hip joint. (Motor to upper leg). Joint names are: 0 2 4 6 -->
  <joint name="0" type="revolute">
    <parent link="hip0"/>
    <child link="upper0"/>
    <axis xyz="0 -1 0"/>
    <origin xyz="0 0.0975 0"/>
    <!--  rpy="0 -0.3 0" -->
    <limit effort="87.5" lower="-6.28318530718" upper="6.28318530718" velocity="30"/>
    <dynamics damping="0.0" friction="0.0"/>
  </joint>
  <!-- Lower leg -->
  <link name="lower0">
    <visual>
      <origin rpy="0 1.5707963268 0" xyz="0.17 0 -0"/>
      <geometry>
        <cylinder length="0.34" radius="0.011"/>
      </geometry>
      <material name="black"/>
    </visual>
    <collision>
      <origin rpy="0 1.5707963268 0" xyz="0.17 0 -0"/>
      <geometry>
        <cylinder length="0.34" radius="0.011"/>
      </geometry>
    </collision>
    <inertial>
      <mass value="0.375"/>
      <inertia ixx="0.00131075" ixy="0" ixz="0" iyy="0.00131075" iyz="0" izz="0.0001"/>
    </inertial>
  </link>
  <!-- Knee joint. Joint names are: 1 3 5 7 -->
  <joint name="1" type="revolute">
    <parent link="upper0"/>
    <child link="lower0"/>
    <axis xyz="0 1 0"/>
    <origin xyz="-0.34 0 0"/>
    <!--rpy="0 0.5 0"-->
    <limit effort="87.5" lower="0" upper="3.14159265359" velocity="30"/>
    <dynamics damping="0.0" friction="0.0"/>
  </joint>
  <!-- Toe -->
  <link name="toe0">
    <contact>
      <friction_anchor/>
      <stiffness value="30000.0"/>
      <damping value="1000.0"/>
      <spinning_friction value="0.3"/>
      <lateral_friction value="3.0"/>
    </contact>
    <visual>
      <origin rpy="0 0 0" xyz="0 0 0"/>
      <geometry>
        <sphere radius="0.03"/>
      </geometry>
      <material name="darkgray"/>
    </visual>
    <collision>
      <origin rpy="0 0 0" xyz="0 0 0"/>
      <geometry>
        <sphere radius="0.03"/>
      </geometry>
    </collision>
    <inertial>
      <mass value="0.15"/>
      <inertia ixx="0.000025" ixy="0" ixz="0" iyy="0.000025" iyz="0" izz="0.000025"/>
    </inertial>
  </link>
  <joint name="jtoe0" type="fixed">
    <parent link="lower0"/>
    <child link="toe0"/>
    <origin xyz="0.34 0 -0.0"/>
    <dynamics damping="0.0" friction="0.0"/>
  </joint>
  <!-- Hip motor -->
  <link name="hip1">
    <visual>
      <origin rpy="1.5707963268 0 0" xyz="0.01 -0.005 0"/>
      <geometry>
        <box size="0.15 0.09 0.15"/>
      </geometry>
      <material name="purple"/>
    </visual>
    <collision>
      <origin rpy="1.5707963268 0 0" xyz="0.0 -0.005 0"/>
      <geometry>
        <box size="0.15 0.09 0.15"/>
      </geometry>
    </collision>
    <inertial>
      <mass value="1.975"/>
      <!-- inertia ixx="1/12*${podMass}*(${podWidth}*${podWidth} + ${podHeight}*${podHeight})"  ixy="0"  ixz="0" iyy="1/12*${podMass}*(${podLength}*${podLength} + ${podWidth}*${podWidth})" iyz="0" izz="1/12*${podMass}*(${podLength}*${podLength} + ${podHeight}*${podHeight})" / -->
      <inertia ixx="0.00891458" ixy="0" ixz="0" iyy="0.0100573" iyz="0" izz="0.01533698"/>
    </inertial>
  </link>
  <!-- Abduction joint. Joint names are: 8 9 10 11 -->
  <joint name="9" type="revolute">
    <parent link="body"/>
    <child link="hip1"/>
    <axis xyz="1 0 0"/>
    <origin xyz="-0.34385 0.092865 0"/>
    <limit effort="375" lower="-0.43" upper="0.43" velocity="8.6"/>
    <dynamics damping="0.0" friction="0.0"/>
  </joint>
  <!-- Upper leg -->
  <link name="upper1">
    <visual>
      <origin rpy="0 0 0" xyz="-0.17 0.0 0"/>
      <geometry>
        <box size="0.34 0.055 0.075"/>
      </geometry>
      <material name="blue"/>
    </visual>
    <collision>
      <origin rpy="0 0 0" xyz="-0.17 0 0"/>
      <geometry>
        <box size="0.34 0.055 0.075"/>
      </geometry>
    </collision>
    <inertial>
      <mass value="2.525"/>
      <!-- inertia ixx="1/12*${upperLegMass}*(${upperLegWidth}*${upperLegWidth} + ${upperLegHeight}*${upperLegHeight})"  ixy="0" ixz="0" iyy="1/12*${upperLegMass}*(${upperLegLength}*${upperLegLength} + ${upperLegHeight}*${upperLegHeight})" iyz="0" izz="1/12*${upperLegMass}*(${upperLegWidth}*${upperLegWidth} + ${upperLegLength}*${upperLegLength})" / -->
      <inertia ixx="0.0003125" ixy="0" ixz="0" iyy="0.0040625" iyz="0" izz="0.0040625"/>
    </inertial>
  </link>
  <!-- Hip joint. (Motor to upper leg). Joint names are: 0 2 4 6 -->
  <joint name="2" type="revolute">
    <parent link="hip1"/>
    <child link="upper1"/>
    <axis xyz="0 -1 0"/>
    <origin xyz="0 0.0975 0"/>
    <!--  rpy="0 -0.3 0" -->
    <limit effort="87.5" lower="-6.28318530718" upper="6.28318530718" velocity="30"/>
    <dynamics damping="0.0" friction="0.0"/>
  </joint>
  <!-- Lower leg -->
  <link name="lower1">
    <visual>
      <origin rpy="0 1.5707963268 0" xyz="0.17 0 -0"/>
      <geometry>
        <cylinder length="0.34" radius="0.011"/>
      </geometry>
      <material name="black"/>
    </visual>
    <collision>
      <origin rpy="0 1.5707963268 0" xyz="0.17 0 -0"/>
      <geometry>
        <cylinder length="0.34" radius="0.011"/>
      </geometry>
    </collision>
    <inertial>
      <mass value="0.375"/>
      <inertia ixx="0.00131075" ixy="0" ixz="0" iyy="0.00131075" iyz="0" izz="0.0001"/>
    </inertial>
  </link>
  <!-- Knee joint. Joint names are: 1 3 5 7 -->
  <joint name="3" type="revolute">
    <parent link="upper1"/>
    <child link="lower1"/>
    <axis xyz="0 1 0"/>
    <origin xyz="-0.34 0 0"/>
    <!--rpy="0 0.5 0"-->
    <limit effort="87.5" lower="0" upper="3.14159265359" velocity="30"/>
    <dynamics damping="0.0" friction="0.0"/>
  </joint>
  <!-- Toe -->
  <link name="toe1">
    <contact>
      <friction_anchor/>
      <stiffness value="30000.0"/>
      <damping value="1000.0"/>
      <spinning_friction value="0.3"/>
      <lateral_friction value="3.0"/>
    </contact>
    <visual>
      <origin rpy="0 0 0" xyz="0 0 0"/>
      <geometry>
        <sphere radius="0.03"/>
      </geometry>
      <material name="darkgray"/>
    </visual>
    <collision>
      <origin rpy="0 0 0" xyz="0 0 0"/>
      <geometry>
        <sphere radius="0.03"/>
      </geometry>
    </collision>
    <inertial>
      <mass value="0.15"/>
      <inertia ixx="0.000025" ixy="0" ixz="0" iyy="0.000025" iyz="0" izz="0.000025"/>
    </inertial>
  </link>
  <joint name="jtoe1" type="fixed">
    <parent link="lower1"/>
    <child link="toe1"/>
    <origin xyz="0.34 0 -0.0"/>
    <dynamics damping="0.0" friction="0.0"/>
  </joint>
  <!-- Hip motor -->
  <link name="hip2">
    <visual>
      <origin rpy="1.5707963268 0 0" xyz="-0.01 0.005 0"/>
      <geometry>
        <box size="0.15 0.09 0.15"/>
      </geometry>
      <material name="purple"/>
    </visual>
    <collision>
      <origin rpy="1.5707963268 0 0" xyz="0.0 0.005 0"/>
      <geometry>
        <box size="0.15 0.09 0.15"/>
      </geometry>
    </collision>
    <inertial>
      <mass value="1.975"/>
      <!-- inertia ixx="1/12*${podMass}*(${podWidth}*${podWidth} + ${podHeight}*${podHeight})"  ixy="0"  ixz="0" iyy="1/12*${podMass}*(${podLength}*${podLength} + ${podWidth}*${podWidth})" iyz="0" izz="1/12*${podMass}*(${podLength}*${podLength} + ${podHeight}*${podHeight})" / -->
      <inertia ixx="0.00891458" ixy="0" ixz="0" iyy="0.0100573" iyz="0" izz="0.01533698"/>
    </inertial>
  </link>
  <!-- Abduction joint. Joint names are: 8 9 10 11 -->
  <joint name="10" type="revolute">
    <parent link="body"/>
    <child link="hip2"/>
    <axis xyz="1 0 0"/>
    <origin xyz="0.34385 -0.092865 0"/>
    <limit effort="375" lower="-0.43" upper="0.43" velocity="8.6"/>
    <dynamics damping="0.0" friction="0.0"/>
  </joint>
  <!-- Upper leg -->
  <link name="upper2">
    <visual>
      <origin rpy="0 0 0" xyz="-0.17 -0.0 0"/>
      <geometry>
        <box size="0.34 0.055 0.075"/>
      </geometry>
      <material name="blue"/>
    </visual>
    <collision>
      <origin rpy="0 0 0" xyz="-0.17 0 0"/>
      <geometry>
        <box size="0.34 0.055 0.075"/>
      </geometry>
    </collision>
    <inertial>
      <mass value="2.525"/>
      <!-- inertia ixx="1/12*${upperLegMass}*(${upperLegWidth}*${upperLegWidth} + ${upperLegHeight}*${upperLegHeight})"  ixy="0" ixz="0" iyy="1/12*${upperLegMass}*(${upperLegLength}*${upperLegLength} + ${upperLegHeight}*${upperLegHeight})" iyz="0" izz="1/12*${upperLegMass}*(${upperLegWidth}*${upperLegWidth} + ${upperLegLength}*${upperLegLength})" / -->
      <inertia ixx="0.0003125" ixy="0" ixz="0" iyy="0.0040625" iyz="0" izz="0.0040625"/>
    </inertial>
  </link>
  <!-- Hip joint. (Motor to upper leg). Joint names are: 0 2 4 6 -->
  <joint name="4" type="revolute">
    <parent link="hip2"/>
    <child link="upper2"/>
    <axis xyz="0 -1 0"/>
    <origin xyz="0 -0.0975 0"/>
    <!--  rpy="0 -0.3 0" -->
    <limit effort="87.5" lower="-6.28318530718" upper="6.28318530718" velocity="30"/>
    <dynamics damping="0.0" friction="0.0"/>
  </joint>
  <!-- Lower leg -->
  <link name="lower2">
    <visual>
      <origin rpy="0 1.5707963268 0" xyz="0.17 0 -0"/>
      <geometry>
        <cylinder length="0.34" radius="0.011"/>
      </geometry>
      <material name="black"/>
    </visual>
    <collision>
      <origin rpy="0 1.5707963268 0" xyz="0.17 0 -0"/>
      <geometry>
        <cylinder length="0.34" radius="0.011"/>
      </geometry>
    </collision>
    <inertial>
      <mass value="0.375"/>
      <inertia ixx="0.00131075" ixy="0" ixz="0" iyy="0.00131075" iyz="0" izz="0.0001"/>
    </inertial>
  </link>
  <!-- Knee joint. Joint names are: 1 3 5 7 -->
  <joint name="5" type="revolute">
    <parent link="upper2"/>
    <child link="lower2"/>
    <axis xyz="0 1 0"/>
    <origin xyz="-0.34 0 0"/>
    <!--rpy="0 0.5 0"-->
    <limit effort="87.5" lower="0" upper="3.14159265359" velocity="30"/>
    <dynamics damping="0.0" friction="0.0"/>
  </joint>
  <!-- Toe -->
  <link name="toe2">
    <contact>
      <friction_anchor/>
      <stiffness value="30000.0"/>
      <damping value="1000.0"/>
      <spinning_friction value="0.3"/>
      <lateral_friction value="3.0"/>
    </contact>
    <visual>
      <origin rpy="0 0 0" xyz="0 0 0"/>
      <geometry>
        <sphere radius="0.03"/>
      </geometry>
      <material name="darkgray"/>
    </visual>
    <collision>
      <origin rpy="0 0 0" xyz="0 0 0"/>
      <geometry>
        <sphere radius="0.03"/>
      </geometry>
    </collision>
    <inertial>
      <mass value="0.15"/>
      <inertia ixx="0.000025" ixy="0" ixz="0" iyy="0.000025" iyz="0" izz="0.000025"/>
    </inertial>
  </link>
  <joint name="jtoe2" type="fixed">
    <parent link="lower2"/>
    <child link="toe2"/>
    <origin xyz="0.34 0 -0.0"/>
    <dynamics damping="0.0" friction="0.0"/>
  </joint>
  <!-- Hip motor -->
  <link name="hip3">
    <visual>
      <origin rpy="1.5707963268 0 0" xyz="0.01 0.005 0"/>
      <geometry>
        <box size="0.15 0.09 0.15"/>
      </geometry>
      <material name="purple"/>
    </visual>
    <collision>
      <origin rpy="1.5707963268 0 0" xyz="0.0 0.005 0"/>
      <geometry>
        <box size="0.15 0.09 0.15"/>
      </geometry>
    </collision>
    <inertial>
      <mass value="1.975"/>
      <!-- inertia ixx="1/12*${podMass}*(${podWidth}*${podWidth} + ${podHeight}*${podHeight})"  ixy="0"  ixz="0" iyy="1/12*${podMass}*(${podLength}*${podLength} + ${podWidth}*${podWidth})" iyz="0" izz="1/12*${podMass}*(${podLength}*${podLength} + ${podHeight}*${podHeight})" / -->
      <inertia ixx="0.00891458" ixy="0" ixz="0" iyy="0.0100573" iyz="0" izz="0.01533698"/>
    </inertial>
  </link>
  <!-- Abduction joint. Joint names are: 8 9 10 11 -->
  <joint name="11" type="revolute">
    <parent link="body"/>
    <child link="hip3"/>
    <axis xyz="1 0 0"/>
    <origin xyz="-0.34385 -0.092865 0"/>
    <limit effort="375" lower="-0.43" upper="0.43" velocity="8.6"/>
    <dynamics damping="0.0" friction="0.0"/>
  </joint>
  <!-- Upper leg -->
  <link name="upper3">
    <visual>
      <origin rpy="0 0 0" xyz="-0.17 -0.0 0"/>
      <geometry>
        <box size="0.34 0.055 0.075"/>
      </geometry>
      <material name="blue"/>
    </visual>
    <collision>
      <origin rpy="0 0 0" xyz="-0.17 0 0"/>
      <geometry>
        <box size="0.34 0.055 0.075"/>
      </geometry>
    </collision>
    <inertial>
      <mass value="2.525"/>
      <!-- inertia ixx="1/12*${upperLegMass}*(${upperLegWidth}*${upperLegWidth} + ${upperLegHeight}*${upperLegHeight})"  ixy="0" ixz="0" iyy="1/12*${upperLegMass}*(${upperLegLength}*${upperLegLength} + ${upperLegHeight}*${upperLegHeight})" iyz="0" izz="1/12*${upperLegMass}*(${upperLegWidth}*${upperLegWidth} + ${upperLegLength}*${upperLegLength})" / -->
      <inertia ixx="0.0003125" ixy="0" ixz="0" iyy="0.0040625" iyz="0" izz="0.0040625"/>
    </inertial>
  </link>
  <!-- Hip joint. (Motor to upper leg). Joint names are: 0 2 4 6 -->
  <joint name="6" type="revolute">
    <parent link="hip3"/>
    <child link="upper3"/>
    <axis xyz="0 -1 0"/>
    <origin xyz="0 -0.0975 0"/>
    <!--  rpy="0 -0.3 0" -->
    <limit effort="87.5" lower="-6.28318530718" upper="6.28318530718" velocity="30"/>
    <dynamics damping="0.0" friction="0.0"/>
  </joint>
  <!-- Lower leg -->
  <link name="lower3">
    <visual>
      <origin rpy="0 1.5707963268 0" xyz="0.17 0 -0"/>
      <geometry>
        <cylinder length="0.34" radius="0.011"/>
      </geometry>
      <material name="black"/>
    </visual>
    <collision>
      <origin rpy="0 1.5707963268 0" xyz="0.17 0 -0"/>
      <geometry>
        <cylinder length="0.34" radius="0.011"/>
      </geometry>
    </collision>
    <inertial>
      <mass value="0.375"/>
      <inertia ixx="0.00131075" ixy="0" ixz="0" iyy="0.00131075" iyz="0" izz="0.0001"/>
    </inertial>
  </link>
  <!-- Knee joint. Joint names are: 1 3 5 7 -->
  <joint name="7" type="revolute">
    <parent link="upper3"/>
    <child link="lower3"/>
    <axis xyz="0 1 0"/>
    <origin xyz="-0.34 0 0"/>
    <!--rpy="0 0.5 0"-->
    <limit effort="87.5" lower="0" upper="3.14159265359" velocity="30"/>
    <dynamics damping="0.0" friction="0.0"/>
  </joint>
  <!-- Toe -->
  <link name="toe3">
    <contact>
      <friction_anchor/>
      <stiffness value="30000.0"/>
      <damping value="1000.0"/>
      <spinning_friction value="0.3"/>
      <lateral_friction value="3.0"/>
    </contact>
    <visual>
      <origin rpy="0 0 0" xyz="0 0 0"/>
      <geometry>
        <sphere radius="0.03"/>
      </geometry>
      <material name="darkgray"/>
    </visual>
    <collision>
      <origin rpy="0 0 0" xyz="0 0 0"/>
      <geometry>
        <sphere radius="0.03"/>
      </geometry>
    </collision>
    <inertial>
      <mass value="0.15"/>
      <inertia ixx="0.000025" ixy="0" ixz="0" iyy="0.000025" iyz="0" izz="0.000025"/>
    </inertial>
  </link>
  <joint name="jtoe3" type="fixed">
    <parent link="lower3"/>
    <child link="toe3"/>
    <origin xyz="0.34 0 -0.0"/>
    <dynamics damping="0.0" friction="0.0"/>
  </joint>
</robot>
